Workbook

Sheet Resumo
A1: Resumo e métricas: ExampleGenerator
A3: Execução dos casos
A4: Casos normativos projetados | B4: =COUNTA('Matriz de casos'!A5:A58)
A5: Casos executados | B5: =COUNTIF('Matriz de casos'!H5:H58,"PASS")+COUNTIF('Matriz de casos'!H5:H58,"FAIL")
A6: PASS | B6: =COUNTIF('Matriz de casos'!H5:H58,"PASS")
A7: FAIL | B7: =COUNTIF('Matriz de casos'!H5:H58,"FAIL")
A8: Invocações JUnit (com parametrizados) | B8: =SUM('Matriz de casos'!L5:L58)
A9: Invocações com falha | B9: 7 (CT-EG-24 x2, CT-EG-25, CT-EG-29, CT-EG-45, CT-EG-48, CT-EG-52)
A10: Famílias de defeito | B10: 4 (F1–F4)
A12: Complexidade ciclomática (JaCoCo)
A13: Classe ExampleGenerator | B13: 112
A14: resolvePropertyToExample(String, String, Schema, Set) | B14: 32
A15: generate(Map, List, String) | B15: 14
A16: generate(Map, List, Schema) | B16: 13
A17: resolveModelToExample(String, String, Schema, Set) | B17: 11
A19: Cobertura JaCoCo da classe (só esta suíte)
A20: Instruções | B20: 97% (1140/1173)
A21: Desvios (branches) | B21: 90% (179/198)
A22: Linhas | B22: 97% (257/266)
A23: Métodos | B23: 100% (13/13)
A25: Ambiente
A26: Baseline | B26: OpenAPI Generator v7.25.0, commit ef964b04480889ef86b56cfae84ade8ad4c91c41
A27: JDK / SO | B27: OpenJDK 22.0.2 / macOS (arm64); compilação no nível Java 11 do projeto
A28: Frameworks | B28: JUnit 5.10.2 (jupiter-api + jupiter-params), JaCoCo 0.8.12

Sheet Oráculos
A1: Oráculos: ExampleGenerator (generate / generateFromResponseSchema)
A2: Regras usadas como base do resultado esperado. O oráculo principal para valores gerados é a OAS 3.0.3 (Schema Object, example: "A free-form property to include an example of an instance for this schema"): o exemplo gerado deve ser uma instância válida do schema. As colunas D–F são calculadas a partir da aba "Matriz de casos".
A4: ID | B4: Regra (comportamento esperado) | C4: Fonte / fundamentação | D4: Nº de casos | E4: PASS | F4: FAIL
A5: R01 | B5: Estrutura da saída: cada entrada tem contentType igual ao tipo de mídia; exemplos gerados trazem generatedContentType (application/json ou application/xml). | C5: Contrato consumido pelos templates (htmlDocs/index.mustache usa {{contentType}} e {{example}}); DefaultCodegen.fromOperation. | D5: =COUNTIF('Matriz de casos'!$C:$C,A5) | E5: =COUNTIFS('Matriz de casos'!$C:$C,A5,'Matriz de casos'!$H:$H,"PASS") | F5: =COUNTIFS('Matriz de casos'!$C:$C,A5,'Matriz de casos'!$H:$H,"FAIL")
A6: R02 | B6: Exemplos explícitos (mapa examples não nulo) prevalecem: uma entrada por chave, com o valor serializado, sem geração. | C6: OAS 3.0.3, Media Type Object: o example "SHALL override the example provided by the schema"; código de generate(Map, List, ...). | D6: =COUNTIF('Matriz de casos'!$C:$C,A6) | E6: =COUNTIFS('Matriz de casos'!$C:$C,A6,'Matriz de casos'!$H:$H,"PASS") | F6: =COUNTIFS('Matriz de casos'!$C:$C,A6,'Matriz de casos'!$H:$H,"FAIL")
A7: R03 | B7: generateFromResponseSchema: devolve null se não há example, $ref nem array; copia statusCode para cada exemplo; o contentType é um dos tipos de producesInfo e o example declarado é preservado. | C7: Uso em DefaultCodegen.fromOperation (examplesForResponse == null é ignorado); OAS 3.0.3 Schema Object example. | D7: =COUNTIF('Matriz de casos'!$C:$C,A7) | E7: =COUNTIFS('Matriz de casos'!$C:$C,A7,'Matriz de casos'!$H:$H,"PASS") | F7: =COUNTIFS('Matriz de casos'!$C:$C,A7,'Matriz de casos'!$H:$H,"FAIL")
A8: R04 | B8: example declarado no schema prevalece sobre valores gerados; example do tipo Date é formatado como yyyy-MM-dd em UTC. | C8: OAS 3.0.3 Schema Object example; comentário no código ("we want to ensure that we're returning a formatted Date"); construtor define TimeZone UTC; issue #17494. | D8: =COUNTIF('Matriz de casos'!$C:$C,A8) | E8: =COUNTIFS('Matriz de casos'!$C:$C,A8,'Matriz de casos'!$H:$H,"PASS") | F8: =COUNTIFS('Matriz de casos'!$C:$C,A8,'Matriz de casos'!$H:$H,"FAIL")
A9: R05 | B9: Tipos de mídia: JSON se começa com application/json ou contém */*; XML se começa com application/xml; lista nula assume application/json; modelo com outro tipo devolve "Custom MIME type example not yet supported: <tipo>"; nada produzido devolve [{output: none}]. | C9: Comentários no código ("assume application/json for this"); ExampleGeneratorTest (upstream). | D9: =COUNTIF('Matriz de casos'!$C:$C,A9) | E9: =COUNTIFS('Matriz de casos'!$C:$C,A9,'Matriz de casos'!$H:$H,"PASS") | F9: =COUNTIFS('Matriz de casos'!$C:$C,A9,'Matriz de casos'!$H:$H,"FAIL")
A10: R06 | B10: Reprodutibilidade: a mesma entrada gera o mesmo exemplo, inclusive para valores numéricos "aleatórios". | C10: Comentário no construtor: "use a fixed seed to make the 'random' numbers reproducible". | D10: =COUNTIF('Matriz de casos'!$C:$C,A10) | E10: =COUNTIFS('Matriz de casos'!$C:$C,A10,'Matriz de casos'!$H:$H,"PASS") | F10: =COUNTIFS('Matriz de casos'!$C:$C,A10,'Matriz de casos'!$H:$H,"FAIL")
A11: R07 | B11: Valores numéricos gerados respeitam minimum, maximum, exclusiveMinimum e exclusiveMaximum. | C11: OAS 3.0.3 Schema Object: example é "an example of an instance for this schema"; JSON Schema Validation wright-00, 5.2 a 5.5. | D11: =COUNTIF('Matriz de casos'!$C:$C,A11) | E11: =COUNTIFS('Matriz de casos'!$C:$C,A11,'Matriz de casos'!$H:$H,"PASS") | F11: =COUNTIFS('Matriz de casos'!$C:$C,A11,'Matriz de casos'!$H:$H,"FAIL")
A12: R08 | B12: Precedência em strings: default > primeiro valor do enum > formato uri/url > nome da propriedade. Boolean: default, senão true. | C12: Código e mensagens de depuração de resolvePropertyToExample ("using property name ... as example"); issue #18622. | D12: =COUNTIF('Matriz de casos'!$C:$C,A12) | E12: =COUNTIFS('Matriz de casos'!$C:$C,A12,'Matriz de casos'!$H:$H,"PASS") | F12: =COUNTIFS('Matriz de casos'!$C:$C,A12,'Matriz de casos'!$H:$H,"FAIL")
A13: R09 | B13: Arrays: comprimento = maxItems (2 se ausente), limitado a 5; itens conforme items; o comprimento respeita minItems. | C13: Comentário "avoid memory issues by limiting to max. 5 items"; JSON Schema Validation wright-00, 5.10 e 5.11. | D13: =COUNTIF('Matriz de casos'!$C:$C,A13) | E13: =COUNTIFS('Matriz de casos'!$C:$C,A13,'Matriz de casos'!$H:$H,"PASS") | F13: =COUNTIFS('Matriz de casos'!$C:$C,A13,'Matriz de casos'!$H:$H,"FAIL")
A14: R10 | B14: Mapas (additionalProperties): objeto com a chave "key" e valor do tipo de additionalProperties. | C14: Código de resolvePropertyToExample (ramo isMapSchema). | D14: =COUNTIF('Matriz de casos'!$C:$C,A14) | E14: =COUNTIFS('Matriz de casos'!$C:$C,A14,'Matriz de casos'!$H:$H,"PASS") | F14: =COUNTIFS('Matriz de casos'!$C:$C,A14,'Matriz de casos'!$H:$H,"FAIL")
A15: R11 | B15: Formatos e tipos: date, date-time, uuid, uri, url e binary têm valores fixos; integer gera número inteiro e number/float/double gera número fracionário. | C15: Código; JSON Schema Validation wright-00, 5.21 (type); issue #17494. | D15: =COUNTIF('Matriz de casos'!$C:$C,A15) | E15: =COUNTIFS('Matriz de casos'!$C:$C,A15,'Matriz de casos'!$H:$H,"PASS") | F15: =COUNTIFS('Matriz de casos'!$C:$C,A15,'Matriz de casos'!$H:$H,"FAIL")
A16: R12 | B16: Modelos: propriedades na ordem de declaração; $ref resolvido para o exemplo do modelo; $ref inexistente não interrompe; ciclos diretos, indiretos e via allOf terminam; type: object gera objeto JSON. | C16: ExampleGeneratorTest.testExamplePropertyOrderPreservation (upstream); issues #23966 e #17497; JSON Schema Validation wright-00, 5.21 (type). | D16: =COUNTIF('Matriz de casos'!$C:$C,A16) | E16: =COUNTIFS('Matriz de casos'!$C:$C,A16,'Matriz de casos'!$H:$H,"PASS") | F16: =COUNTIFS('Matriz de casos'!$C:$C,A16,'Matriz de casos'!$H:$H,"FAIL")
A17: R13 | B17: Composição: allOf combina as propriedades de todas as partes; oneOf/anyOf usa a primeira alternativa com $ref resolvível; modelo array/enum de nível superior gera array/primeiro valor. | C17: Issues #17497 e #18443; código de resolveModelToExample. | D17: =COUNTIF('Matriz de casos'!$C:$C,A17) | E17: =COUNTIFS('Matriz de casos'!$C:$C,A17,'Matriz de casos'!$H:$H,"PASS") | F17: =COUNTIFS('Matriz de casos'!$C:$C,A17,'Matriz de casos'!$H:$H,"FAIL")

Sheet Matriz de casos
A1: Matriz de casos: ExampleGeneratorJUnitTest (JUnit 5, @Nested + @ParameterizedTest)
A2: Executada em 12/10/2026 via Maven (Surefire), commit ef964b04480889ef86b56cfae84ade8ad4c91c41. Casos parametrizados contam como um caso normativo; a coluna L mostra quantas invocações o JUnit executou. Coluna J: família de defeito (ver aba Defeitos). Os casos CT-EG-49 a CT-EG-54 foram projetados depois da primeira medição de cobertura, para os ramos ainda não exercitados; cada um tem justificativa funcional (regra da coluna C).
A4: ID | B4: Grupo | C4: Regra | D4: Técnica | E4: Entrada | F4: Resultado esperado | G4: Resultado obtido | H4: Status | I4: Família | J4: Método JUnit | K4: Classe @Nested | L4: Invocações
A5: CT-EG-01 | B5: Saída e mídia | C5: R02 | D5: Partição: exemplos explícitos presentes | E5: generate({json:{id:1}, xml:"<id>1</id>"}, [json], IntegerSchema) | F5: 2 entradas, uma por chave, valores serializados, sem generatedContentType | G5: Conforme esperado | H5: PASS | J5: explicitExamplesWin | K5: OutputStructure | L5: 1
A6: CT-EG-02 | B6: Saída e mídia | C6: R05 | D6: Valor-limite: lista de mídia nula | E6: generate(null, null, BooleanSchema) | F6: 1 entrada application/json com example true | G6: Conforme esperado | H6: PASS | J6: nullMediaTypesDefaultToJson | K6: OutputStructure | L6: 1
A7: CT-EG-03 | B7: Saída e mídia | C7: R05 | D7: Partição: tipos compatíveis com JSON (parametrizado) | E7: application/json; application/json; charset=utf-8; */* | F7: generatedContentType application/json, contentType preservado | G7: Conforme esperado (3/3) | H7: PASS | J7: jsonCompatibleMediaTypes | K7: OutputStructure | L7: 3
A8: CT-EG-04 | B8: Saída e mídia | C8: R05 | D8: Partição: modelo em XML | E8: Pet{name example Rex}, [application/xml] | F8: Exemplo XML com <name>Rex</name> | G8: Conforme esperado | H8: PASS | J8: modelAsXml | K8: OutputStructure | L8: 1
A9: CT-EG-05 | B9: Saída e mídia | C9: R05 | D9: Partição: tipo de mídia não suportado (modelo) | E9: Pet, [text/plain] | F9: "Custom MIME type example not yet supported: text/plain" | G9: Conforme esperado | H9: PASS | J9: modelWithCustomMediaType | K9: OutputStructure | L9: 1
A10: CT-EG-06 | B10: Saída e mídia | C10: R05 | D10: Partição: nada produzível (propriedade) | E10: StringSchema, [text/plain] | F10: [{output: none}] | G10: Conforme esperado | H10: PASS | J10: nothingProducible | K10: OutputStructure | L10: 1
A11: CT-EG-07 | B11: Saída e mídia | C11: R05 | D11: Partição: modelo inexistente | E11: "DoesNotExist", [json] | F11: [{output: none}] | G11: Conforme esperado | H11: PASS | J11: unknownModel | K11: OutputStructure | L11: 1
A12: CT-EG-08 | B12: generateFromResponseSchema | C12: R03 | D12: Partição: $ref com dois tipos de mídia | E12: "201", $ref Pet, {json, xml} | F12: 2 exemplos, ambos com statusCode 201 | G12: Conforme esperado | H12: PASS | J12: statusCodeOnEveryExample | K12: FromResponseSchema | L12: 1
A13: CT-EG-09 | B13: generateFromResponseSchema | C13: R03 | D13: Partição: sem example, sem $ref, não array | E13: StringSchema sem example | F13: null | G13: Conforme esperado | H13: PASS | J13: noExampleNoRefNoArray | K13: FromResponseSchema | L13: 1
A14: CT-EG-10 | B14: generateFromResponseSchema | C14: R03 | D14: Partição: example primitivo | E14: StringSchema example "pong" | F14: example "pong" em JSON, statusCode 200 | G14: Conforme esperado | H14: PASS | J14: primitiveExample | K14: FromResponseSchema | L14: 1
A15: CT-EG-11 | B15: generateFromResponseSchema | C15: R03 | D15: Partição: array de primitivos | E15: ArraySchema items boolean | F15: Array JSON de booleanos true | G15: Conforme esperado | H15: PASS | J15: arrayResponse | K15: FromResponseSchema | L15: 1
A16: CT-EG-12 | B16: Precedência | C16: R04 | D16: Partição: example declarado x restrição | E16: integer minimum 100, example 42 | F16: 42 | G16: Conforme esperado | H16: PASS | J16: declaredExampleWins | K16: ValuePrecedence | L16: 1
... A27: CT-EG-23 | B27: Restrições numéricas | C27: R07 | D27: Valor-limite: minimum = maximum | E27: integer [7, 7] | F27: 7 | G27: Conforme esperado | H27: PASS | J27: degenerateRange | K27: NumericConstraints | L27: 1
A28: CT-EG-24 | B28: Restrições numéricas | C28: R07 | D28: Partição: só maximum negativo (parametrizado integer/number) | E28: maximum -5 | F28: valor <= -5 | G28: integer: 0; number: -0.40041409523050575 (randomNumber calcula random * max, que fica em (max, 0]) | H28: FAIL | I28: F1 | J28: negativeMaximumOnly | K28: NumericConstraints | L28: 2
A29: CT-EG-25 | B29: Restrições numéricas | C29: R07 | D29: Valor-limite: minimum exclusivo em integer | E29: integer minimum 0, exclusiveMinimum true | F29: valor > 0 | G29: 0 (exclusiveMinimum ignorado; random + 0 truncado para int) | H29: FAIL | I29: F1 | J29: integerExclusiveMinimum | K29: NumericConstraints | L29: 1
A30: CT-EG-26 | B30: Restrições numéricas | C30: R07 | D30: Valor-limite: maximum exclusivo em number | E30: number [0, 1), exclusiveMaximum true | F30: 0 <= valor < 1 | G30: Conforme esperado | H30: PASS | J30: numberExclusiveMaximum | K30: NumericConstraints | L30: 1
A31: CT-EG-27 | B31: Arrays | C31: R09 | D31: Valor-limite: maxItems (parametrizado) | E31: maxItems ausente, 0, 1, 3, 5, 6, 100 | F31: 2, 0, 1, 3, 5, 5, 5 itens | G31: Conforme esperado (7/7) | H31: PASS | J31: lengthFollowsMaxItemsWithCapOfFive | K31: ArrayExamples | L31: 7
A32: CT-EG-28 | B32: Arrays | C32: R09 | D32: Partição: itens conforme items | E32: array de uuid | F32: Todos os itens são o uuid fixo | G32: Conforme esperado | H32: PASS | J32: itemsFollowItemSchema | K32: ArrayExamples | L32: 1
A33: CT-EG-29 | B33: Arrays | C33: R09 | D33: Valor-limite: minItems acima do padrão | E33: minItems 3, sem maxItems | F33: Ao menos 3 itens | G33: 2 itens (minItems ignorado) | H33: FAIL | I33: F2 | J33: minItemsIsRespected | K33: ArrayExamples | L33: 1
A34: CT-EG-30 | B34: Mapas | C34: R10 | D34: Partição: additionalProperties | E34: map de date | F34: {"key": "2000-01-23"} | G34: Conforme esperado | H34: PASS | J34: mapUsesKeyPlaceholder | K34: Maps | L34: 1
A35: CT-EG-31 | B35: Modelos | C35: R12 | D35: Partição: modelo com várias propriedades | E35: Pet{id, name, born} | F35: Chaves na ordem id, name, born | G35: Conforme esperado | H35: PASS | J35: propertyOrder | K35: Models | L35: 1
A36: CT-EG-32 | B36: Modelos | C36: R12 | D36: Partição: $ref aninhado | E36: Pet.category -> Category{label: dogs} | F36: category.label = dogs | G36: Conforme esperado | H36: PASS | J36: nestedReference | K36: Models | L36: 1
A37: CT-EG-33 | B37: Modelos | C37: R12 | D37: Partição: $ref inexistente | E37: Pet.owner -> Missing | F37: Geração continua; owner presente; id = 3 | G37: Conforme esperado | H37: PASS | J37: danglingReference | K37: Models | L37: 1
A38: CT-EG-34 | B38: Modelos | C38: R12 | D38: Estrutura: autorreferência | E38: Node.next -> Node | F38: Termina; next ausente/nulo | G38: Conforme esperado | H38: PASS | J38: selfReferenceTerminates | K38: Models | L38: 1
A39: CT-EG-35 | B39: Modelos | C39: R12 | D39: Estrutura: ciclo indireto | E39: A.b -> B, B.a -> A | F39: Termina; b é objeto | G39: Conforme esperado | H39: PASS | J39: indirectCycleTerminates | K39: Models | L39: 1
A40: CT-EG-36 | B40: Composição | C40: R13 | D40: Partição: allOf ref + inline | E40: Dog allOf [Animal, {barks}] | F40: name = Rex e barks = true | G40: Conforme esperado | H40: PASS | J40: allOfMergesProperties | K40: Models | L40: 1
A41: CT-EG-37 | B41: Composição | C41: R13 | D41: Partição: oneOf/anyOf com ref inválido primeiro (parametrizado) | E41: oneOf [Missing, Cat, Dog]; anyOf [Missing, Cat, Dog] | F41: kind = cat nos dois casos | G41: Conforme esperado (2/2) | H41: PASS | J41: firstResolvableAlternative | K41: Models | L41: 2
A42: CT-EG-38 | B42: Composição | C42: R13 | D42: Partição: enum de nível superior | E42: Status enum [placed, approved] | F42: "placed" | G42: Conforme esperado | H42: PASS | J42: topLevelEnumModel | K42: Models | L42: 1
A43: CT-EG-39 | B43: Reprodutibilidade | C43: R06 | D43: Comparação entre instâncias | E43: Measure{int, double, float, int64>=1000} em 2 geradores | F43: Saídas idênticas | G43: Conforme esperado | H43: PASS | J43: sameInputSameOutput | K43: Determinism | L43: 1
A44: CT-EG-40 | B44: Reprodutibilidade | C44: R06 | D44: Chamadas repetidas | E44: Mesmo gerador chamado 2 vezes | F44: Exemplos idênticos | G44: Conforme esperado (o 2º vem do example gravado no schema; ver E1) | H44: PASS | J44: repeatedCallsAreStable | K44: Determinism | L44: 1
A45: CT-EG-41 | B45: Saída e mídia | C45: R05 | D45: Partição: propriedade em XML | E45: StringSchema example abc, [xml] | F45: Exemplo XML contendo abc, generatedContentType xml | G45: Conforme esperado | H45: PASS | J45: propertyAsXml | K45: OutputStructure | L45: 1
... A48: CT-EG-44 | B48: generateFromResponseSchema | C48: R03 | D48: Partição: example primitivo por tipo de mídia (parametrizado) | E48: example "pong" com produces {xml}; {text/plain}; {*/*} | F48: output none; output none; "pong" como JSON | G48: Conforme esperado (3/3) | H48: PASS | J48: primitiveExampleByMediaType | K48: FromResponseSchema | L48: 3
A49: CT-EG-45 | B49: generateFromResponseSchema | C49: R03 | D49: Partição: objeto inline com example objeto (java.util.Map) | E49: ObjectSchema{id,name}, example Map{id:1,name:Rex}, {json} | F49: 1 exemplo, contentType application/json, example {id:1,name:Rex} | G49: 2 exemplos com contentType "name" e "id" (as chaves do example viram tipos de mídia) | H49: FAIL | I49: F3 | J49: inlineObjectExample | K49: FromResponseSchema | L49: 1
A50: CT-EG-46 | B50: Composição | C50: R12 | D50: Estrutura: ciclo via allOf | E50: A allOf [B, {fromA}], B allOf [A, {fromB}] | F50: Termina; fromA = 1 e fromB = 2 | G50: Conforme esperado | H50: PASS | J50: allOfCycleTerminates | K50: Models | L50: 1
A51: CT-EG-47 | B51: Composição | C51: R13 | D51: Partição: array de nível superior | E51: Tags: array de date | F51: Array com "2000-01-23" | G51: Conforme esperado | H51: PASS | J51: topLevelArrayModel | K51: Models | L51: 1
A52: CT-EG-48 | B52: Modelos | C52: R12 | D52: Partição: object sem propriedades | E52: propriedade metadata: type object | F52: Objeto JSON | G52: String "{}" | H52: FAIL | I52: F4 | J52: emptyInlineObjectIsJsonObject | K52: Models | L52: 1
A53: CT-EG-49 | B53: Saída e mídia | C53: R05 | D53: Valor-limite: schema nulo (parametrizado) | E53: generate(null, [json]|[xml], (Schema) null) | F53: [{output: none}] | G53: Conforme esperado (2/2) | H53: PASS | J53: nullProperty | K53: OutputStructure | L53: 2
...

Sheet Defeitos
A1: Divergências (famílias de defeito)
A3: Família | B3: Casos | C3: Descrição | D3: Causa (análise do código) | E3: Reprodução pela CLI (CTM-EG-01) | F3: Severidade | G3: Prioridade | H3: Issue
A4: F1 | B4: CT-EG-24 (integer e number), CT-EG-25 | C4: Valor numérico gerado viola maximum (só maximum, negativo) ou exclusiveMinimum. | D4: randomNumber(min, max) com só max devolve random.nextDouble() * max, que fica em (max, 0] quando max < 0; exclusiveMinimum/exclusiveMaximum nunca são lidos, e com minimum 0 em integer o valor é truncado para 0. | E4: Sim, passo 4 (celsius: 0 com maximum -5; level: 0 com minimum 0 exclusivo). | F4: Média: o exemplo aparece em documentação e em stubs (Spring, WireMock, ASP.NET) e falha na validação do próprio schema. | G4: Média | H4: [preencher nº]
A5: F2 | B5: CT-EG-29 | C5: Array gerado tem menos itens que minItems. | D5: O comprimento usa só maxItems (padrão 2, limite 5); minItems nunca é lido. | E5: Sim, passo 5 (samples: [7, 7] com minItems 3). | F5: Média | G5: Média | H5: [preencher nº]
A6: F3 | B6: CT-EG-45 | C6: Schema inline com example objeto (java.util.Map) em generateFromResponseSchema: as chaves do example viram tipos de mídia e cada valor vira um exemplo separado. | D6: O ramo "primitive type" faz cast do example para Map<String,Object> e chama generate(Map, ...), que interpreta o mapa como {tipo de mídia -> exemplo}. | E6: Não: o swagger-parser entrega o example como ObjectNode (não Map); afeta uso programático da biblioteca. | F6: Baixa | G6: Baixa | H6: [preencher nº]
A7: F4 | B7: CT-EG-48, CT-EG-52 | C7: type: object sem properties gera exemplo com tipo errado: a string "{}" quando é propriedade (CT-EG-48; o mesmo vale para $ref inexistente) e null quando é modelo de nível superior (CT-EG-52). | D7: resolvePropertyToExample devolve o literal String "{}", que o Json.pretty serializa como string; resolveModelToExample devolve null para modelo sem properties, sem composição e que não é array/enum. | E7: Propriedade: sim, passo 6 (metadata: "{}"). Modelo de nível superior: não; pela CLI o modelo é "desembrulhado" (unaliasSchema) e a operação fica sem Example data. | F7: Baixa: exemplo com tipo errado; clientes que fazem parse do exemplo recebem string. | G7: Baixa | H7: [preencher nº]

Sheet Fora da suíte normativa
A1: Observações exploratórias (sem oráculo fundamentado; não classificadas como defeito)
A3: ID | B3: Observação | C3: Por que ficou fora da suíte normativa
A4: E1 | B4: resolveModelToExample grava o exemplo gerado no schema de entrada (schema.setExample(values)): o modelo OpenAPI é alterado como efeito colateral, e chamadas seguintes devolvem o exemplo gravado (é o que faz CT-EG-40 passar). Confirmado por execução: example do schema passa de null para {id=1} após generate. | C4: Nenhuma documentação proíbe a mutação; pode ser cache intencional. Fica como risco para a Entrega 2 (testes de integração).
A5: E2 | B5: Strings ignoram minLength, maxLength e pattern: o fallback usa o nome da propriedade (ex.: "status" com maxLength 2). | C5: O próprio código registra o fallback ("using property name as example"): é uma limitação conhecida (melhoria), não uma regra implementada errada.
A6: E3 | B6: oneOf/anyOf sem nenhuma alternativa resolvível gera o exemplo "null" (confirmado por execução em 12/10/2026). | C6: Não há fonte que diga o que deveria ser gerado nesse caso.
A7: E4 | B7: Resposta array sem items em generateFromResponseSchema devolve null (comentário TODO no código). | C7: O próprio código marca o caso como não tratado (TODO).
A8: E5 | B8: multipleOf é ignorado em números gerados. | C8: Mesmo oráculo de R07, mas deixado para a Entrega 2 para manter o escopo da Entrega 1.
A9: E6 | B9: generate(null, mediaTypes, (String) null) — nome de modelo nulo — devolve "Custom MIME type example not yet supported: application/json", mensagem que diz que JSON não é suportado. | C9: Nenhuma fonte define a saída para modelo nulo; o caso foi projetado para CT-EG-49 e retirado da suíte normativa por falta de oráculo.
